[
   {
      "author_association" : "MEMBER",
      "body" : "For reference, the assert in `sync.cpp` has been changed to `std::abort` in https://github.com/bitcoin/bitcoin/pull/11640#discussion_r154455316\r\n\r\nDestructors are not called on `std::abort`, see https://en.cppreference.com/w/cpp/utility/program/abort\r\n\r\nThus, the thread group keeps running forever: https://github.com/bitcoin/bitcoin/blob/442a9c64775454a7073aff9872721c58b1dd35c5/src/test/setup_common.cpp#L111-L114",
      "created_at" : "2019-08-23T18:45:31Z",
      "html_url" : "https://github.com/bitcoin/bitcoin/issues/16700#issuecomment-524422244",
      "id" : 524422244,
      "issue_url" : "https://api.github.com/repos/bitcoin/bitcoin/issues/16700",
      "node_id" : "MDEyOklzc3VlQ29tbWVudDUyNDQyMjI0NA==",
      "updated_at" : "2019-08-23T18:45:31Z",
      "url" : "https://api.github.com/repos/bitcoin/bitcoin/issues/comments/524422244",
      "user" : {
         "avatar_url" : "https://avatars0.githubusercontent.com/u/6399679?v=4",
         "events_url" : "https://api.github.com/users/MarcoFalke/events{/privacy}",
         "followers_url" : "https://api.github.com/users/MarcoFalke/followers",
         "following_url" : "https://api.github.com/users/MarcoFalke/following{/other_user}",
         "gists_url" : "https://api.github.com/users/MarcoFalke/gists{/gist_id}",
         "gravatar_id" : "",
         "html_url" : "https://github.com/MarcoFalke",
         "id" : 6399679,
         "login" : "MarcoFalke",
         "node_id" : "MDQ6VXNlcjYzOTk2Nzk=",
         "organizations_url" : "https://api.github.com/users/MarcoFalke/orgs",
         "received_events_url" : "https://api.github.com/users/MarcoFalke/received_events",
         "repos_url" : "https://api.github.com/users/MarcoFalke/repos",
         "site_admin" : false,
         "starred_url" : "https://api.github.com/users/MarcoFalke/starred{/owner}{/repo}",
         "subscriptions_url" : "https://api.github.com/users/MarcoFalke/subscriptions",
         "type" : "User",
         "url" : "https://api.github.com/users/MarcoFalke"
      }
   },
   {
      "author_association" : "MEMBER",
      "body" : "Seems we need to set BOOST_TEST_CATCH_SYSTEM_ERRORS somewhere and write an handler for abort signal.\r\n\r\nhttps://www.boost.org/doc/libs/1_71_0/libs/test/doc/html/boost_test/utf_reference/rt_param_reference/catch_system.html\r\n\r\nEDIT: \r\n\r\n```\r\n$> ./src/test/test_bitcoin --catch_system_errors=no -t wallet_tests \r\nRunning 9 test cases...\r\nAssertion failed: detected inconsistent lock order at sync.cpp:121, details in debug log.\r\n[1]    8770 abort      ./src/test/test_bitcoin --catch_system_errors=no -t wallet_tests\r\n```\r\n\r\nIn fact, abort signals are catched which explains why we see checkpoints, but boost seems to not call destructor\r\n\r\n",
      "created_at" : "2019-08-23T19:04:55Z",
      "html_url" : "https://github.com/bitcoin/bitcoin/issues/16700#issuecomment-524428235",
      "id" : 524428235,
      "issue_url" : "https://api.github.com/repos/bitcoin/bitcoin/issues/16700",
      "node_id" : "MDEyOklzc3VlQ29tbWVudDUyNDQyODIzNQ==",
      "performed_via_github_app" : null,
      "updated_at" : "2019-08-23T19:34:23Z",
      "url" : "https://api.github.com/repos/bitcoin/bitcoin/issues/comments/524428235",
      "user" : {
         "avatar_url" : "https://avatars.githubusercontent.com/u/23310655?v=4",
         "events_url" : "https://api.github.com/users/ariard/events{/privacy}",
         "followers_url" : "https://api.github.com/users/ariard/followers",
         "following_url" : "https://api.github.com/users/ariard/following{/other_user}",
         "gists_url" : "https://api.github.com/users/ariard/gists{/gist_id}",
         "gravatar_id" : "",
         "html_url" : "https://github.com/ariard",
         "id" : 23310655,
         "login" : "ariard",
         "node_id" : "MDQ6VXNlcjIzMzEwNjU1",
         "organizations_url" : "https://api.github.com/users/ariard/orgs",
         "received_events_url" : "https://api.github.com/users/ariard/received_events",
         "repos_url" : "https://api.github.com/users/ariard/repos",
         "site_admin" : false,
         "starred_url" : "https://api.github.com/users/ariard/starred{/owner}{/repo}",
         "subscriptions_url" : "https://api.github.com/users/ariard/subscriptions",
         "type" : "User",
         "url" : "https://api.github.com/users/ariard"
      }
   },
   {
      "author_association" : "MEMBER",
      "body" : "@MarcoFalke \r\n\r\nDigging up, AFAIU the issue was solved in #18183 by setting `catch_system_errors=no` in the ci. That said if we're willingly to exercise asserts, have we found a way to teach the unit test framework how to handle them ?\r\n\r\nOr otherwise do you advise to replace them by exceptions and catching them with BOOST_CHECK_THROW ?\r\n\r\nInterested in the context of #21515's test coverage.",
      "created_at" : "2021-04-29T18:34:17Z",
      "html_url" : "https://github.com/bitcoin/bitcoin/issues/16700#issuecomment-829494172",
      "id" : 829494172,
      "issue_url" : "https://api.github.com/repos/bitcoin/bitcoin/issues/16700",
      "node_id" : "MDEyOklzc3VlQ29tbWVudDgyOTQ5NDE3Mg==",
      "performed_via_github_app" : null,
      "updated_at" : "2021-04-29T18:34:17Z",
      "url" : "https://api.github.com/repos/bitcoin/bitcoin/issues/comments/829494172",
      "user" : {
         "avatar_url" : "https://avatars.githubusercontent.com/u/23310655?v=4",
         "events_url" : "https://api.github.com/users/ariard/events{/privacy}",
         "followers_url" : "https://api.github.com/users/ariard/followers",
         "following_url" : "https://api.github.com/users/ariard/following{/other_user}",
         "gists_url" : "https://api.github.com/users/ariard/gists{/gist_id}",
         "gravatar_id" : "",
         "html_url" : "https://github.com/ariard",
         "id" : 23310655,
         "login" : "ariard",
         "node_id" : "MDQ6VXNlcjIzMzEwNjU1",
         "organizations_url" : "https://api.github.com/users/ariard/orgs",
         "received_events_url" : "https://api.github.com/users/ariard/received_events",
         "repos_url" : "https://api.github.com/users/ariard/repos",
         "site_admin" : false,
         "starred_url" : "https://api.github.com/users/ariard/starred{/owner}{/repo}",
         "subscriptions_url" : "https://api.github.com/users/ariard/subscriptions",
         "type" : "User",
         "url" : "https://api.github.com/users/ariard"
      }
   },
   {
      "author_association" : "MEMBER",
      "body" : "I think if you want to exercise a logic error during a unit test, the only way is to throw something, as an assert would abort the process.",
      "created_at" : "2021-04-29T18:39:23Z",
      "html_url" : "https://github.com/bitcoin/bitcoin/issues/16700#issuecomment-829497403",
      "id" : 829497403,
      "issue_url" : "https://api.github.com/repos/bitcoin/bitcoin/issues/16700",
      "node_id" : "MDEyOklzc3VlQ29tbWVudDgyOTQ5NzQwMw==",
      "performed_via_github_app" : null,
      "updated_at" : "2021-04-29T18:39:23Z",
      "url" : "https://api.github.com/repos/bitcoin/bitcoin/issues/comments/829497403",
      "user" : {
         "avatar_url" : "https://avatars.githubusercontent.com/u/6399679?v=4",
         "events_url" : "https://api.github.com/users/MarcoFalke/events{/privacy}",
         "followers_url" : "https://api.github.com/users/MarcoFalke/followers",
         "following_url" : "https://api.github.com/users/MarcoFalke/following{/other_user}",
         "gists_url" : "https://api.github.com/users/MarcoFalke/gists{/gist_id}",
         "gravatar_id" : "",
         "html_url" : "https://github.com/MarcoFalke",
         "id" : 6399679,
         "login" : "MarcoFalke",
         "node_id" : "MDQ6VXNlcjYzOTk2Nzk=",
         "organizations_url" : "https://api.github.com/users/MarcoFalke/orgs",
         "received_events_url" : "https://api.github.com/users/MarcoFalke/received_events",
         "repos_url" : "https://api.github.com/users/MarcoFalke/repos",
         "site_admin" : false,
         "starred_url" : "https://api.github.com/users/MarcoFalke/starred{/owner}{/repo}",
         "subscriptions_url" : "https://api.github.com/users/MarcoFalke/subscriptions",
         "type" : "User",
         "url" : "https://api.github.com/users/MarcoFalke"
      }
   },
   {
      "author_association" : "MEMBER",
      "body" : "Thanks for the answer! Yes a lot of critical code paths with asserts aren't exercise sadly.",
      "created_at" : "2021-04-30T15:10:39Z",
      "html_url" : "https://github.com/bitcoin/bitcoin/issues/16700#issuecomment-830163396",
      "id" : 830163396,
      "issue_url" : "https://api.github.com/repos/bitcoin/bitcoin/issues/16700",
      "node_id" : "MDEyOklzc3VlQ29tbWVudDgzMDE2MzM5Ng==",
      "performed_via_github_app" : null,
      "updated_at" : "2021-04-30T15:10:39Z",
      "url" : "https://api.github.com/repos/bitcoin/bitcoin/issues/comments/830163396",
      "user" : {
         "avatar_url" : "https://avatars.githubusercontent.com/u/23310655?v=4",
         "events_url" : "https://api.github.com/users/ariard/events{/privacy}",
         "followers_url" : "https://api.github.com/users/ariard/followers",
         "following_url" : "https://api.github.com/users/ariard/following{/other_user}",
         "gists_url" : "https://api.github.com/users/ariard/gists{/gist_id}",
         "gravatar_id" : "",
         "html_url" : "https://github.com/ariard",
         "id" : 23310655,
         "login" : "ariard",
         "node_id" : "MDQ6VXNlcjIzMzEwNjU1",
         "organizations_url" : "https://api.github.com/users/ariard/orgs",
         "received_events_url" : "https://api.github.com/users/ariard/received_events",
         "repos_url" : "https://api.github.com/users/ariard/repos",
         "site_admin" : false,
         "starred_url" : "https://api.github.com/users/ariard/starred{/owner}{/repo}",
         "subscriptions_url" : "https://api.github.com/users/ariard/subscriptions",
         "type" : "User",
         "url" : "https://api.github.com/users/ariard"
      }
   },
   {
      "author_association" : "MEMBER",
      "body" : "Obviously that assumes the logic error is reachable during the unit test. If it is not reachable, an `Assert` is just fine. If the program may continue execution, an `Assume` is also fine. See `./src/util/check.h` and the dev notes.",
      "created_at" : "2021-04-30T15:23:01Z",
      "html_url" : "https://github.com/bitcoin/bitcoin/issues/16700#issuecomment-830171632",
      "id" : 830171632,
      "issue_url" : "https://api.github.com/repos/bitcoin/bitcoin/issues/16700",
      "node_id" : "MDEyOklzc3VlQ29tbWVudDgzMDE3MTYzMg==",
      "performed_via_github_app" : null,
      "updated_at" : "2021-04-30T15:23:01Z",
      "url" : "https://api.github.com/repos/bitcoin/bitcoin/issues/comments/830171632",
      "user" : {
         "avatar_url" : "https://avatars.githubusercontent.com/u/6399679?v=4",
         "events_url" : "https://api.github.com/users/MarcoFalke/events{/privacy}",
         "followers_url" : "https://api.github.com/users/MarcoFalke/followers",
         "following_url" : "https://api.github.com/users/MarcoFalke/following{/other_user}",
         "gists_url" : "https://api.github.com/users/MarcoFalke/gists{/gist_id}",
         "gravatar_id" : "",
         "html_url" : "https://github.com/MarcoFalke",
         "id" : 6399679,
         "login" : "MarcoFalke",
         "node_id" : "MDQ6VXNlcjYzOTk2Nzk=",
         "organizations_url" : "https://api.github.com/users/MarcoFalke/orgs",
         "received_events_url" : "https://api.github.com/users/MarcoFalke/received_events",
         "repos_url" : "https://api.github.com/users/MarcoFalke/repos",
         "site_admin" : false,
         "starred_url" : "https://api.github.com/users/MarcoFalke/starred{/owner}{/repo}",
         "subscriptions_url" : "https://api.github.com/users/MarcoFalke/subscriptions",
         "type" : "User",
         "url" : "https://api.github.com/users/MarcoFalke"
      }
   }
]
